<!-- Cheetah Model

    The state space is populated with joints in the order that they are
    defined in this file. The actuators also operate on joints.

    State-Space (name/joint/parameter):
        - rootx     slider      position (m)
        - rootz     slider      position (m)
        - rooty     hinge       angle (rad)
        - bthigh    hinge       angle (rad)
        - bshin     hinge       angle (rad)
        - bfoot     hinge       angle (rad)
        - fthigh    hinge       angle (rad)
        - fshin     hinge       angle (rad)
        - ffoot     hinge       angle (rad)
        - rootx     slider      velocity (m/s)
        - rootz     slider      velocity (m/s)
        - rooty     hinge       angular velocity (rad/s)
        - bthigh    hinge       angular velocity (rad/s)
        - bshin     hinge       angular velocity (rad/s)
        - bfoot     hinge       angular velocity (rad/s)
        - fthigh    hinge       angular velocity (rad/s)
        - fshin     hinge       angular velocity (rad/s)
        - ffoot     hinge       angular velocity (rad/s)

    Actuators (name/actuator/parameter):
        - bthigh    hinge       torque (N m)
        - bshin     hinge       torque (N m)
        - bfoot     hinge       torque (N m)
        - fthigh    hinge       torque (N m)
        - fshin     hinge       torque (N m)
        - ffoot     hinge       torque (N m)

-->
{% set torso_length=size[0]|default(1) %}
{% set head_angle=0.87 %}
{% set head_size=size[1]|default(0.15) %}

{% set bthigh_angle=-3.8 %}
{% set bthigh_size=size[2]|default(0.145) %}
{% set bshin_angle=-2.03 %}
{% set bshin_size=size[3]|default(0.15) %}
{% set bfoot_angle=-0.27 %}
{% set bfoot_size=size[4]|default(0.094) %}

{% set fthigh_angle=0.52 %}
{% set fthigh_size=size[5]|default(0.133) %}
{% set fshin_angle=-0.6%}
{% set fshin_size=size[6]|default(0.106) %}
{% set ffoot_angle=-0.6 %}
{% set ffoot_size=size[7]|default(0.07) %}

<mujoco model="cheetah">
  <compiler angle="radian" coordinate="local" inertiafromgeom="true" settotalmass="14"/>
  <default>
    <joint armature=".1" damping=".01" limited="true" solimplimit="0 .8 .03" solreflimit=".02 1" stiffness="8"/>
    <geom conaffinity="0" condim="3" contype="1" friction=".4 .1 .1" rgba="0.8 0.6 .4 1" solimp="0.0 0.8 0.01" solref="0.02 1"/>
    <motor ctrllimited="true" ctrlrange="-1 1"/>


    <!-- http://mujoco.org/book/XMLreference.html#pair -->
    <!-- two tangential, one torsional, two rolling (with condim=3 I only used the first two tangential)-->
    <default class="foot-floor">
           <pair condim="3" friction=".4 .4 .1 .1 .1" solimp="0.0 0.8 0.01" solref="0.02 1"/> <!-- Earlier the solimp and solref parameters were different because the default values were used! 2.0 IS INDEED THE TARGET FRICTION VALUE -->
    </default>
  </default>
  <size nstack="300000" nuser_geom="1"/>

  
  <!-- <option gravity="0 0 -9.81" timestep="0.01"/> -->
  <!-- The warmstart flag should be disabled whenever we set the states in random orders so that no information from previous state computations is used. -->
  <option gravity="0 0 -9.81" timestep="0.01">
     <flag warmstart="disable" /> 
  </option>

  <asset>
    <texture builtin="gradient" height="100" rgb1="1 1 1" rgb2="0 0 0" type="skybox" width="100"/>
    <texture builtin="flat" height="1278" mark="cross" markrgb="1 1 1" name="texgeom" random="0.01" rgb1="0.8 0.6 0.4" rgb2="0.8 0.6 0.4" type="cube" width="127"/>
    <texture builtin="checker" height="100" name="texplane" rgb1="0 0 0" rgb2="0.8 0.8 0.8" type="2d" width="100"/>
    <material name="MatPlane" reflectance="0.5" shininess="1" specular="1" texrepeat="60 60" texture="texplane"/>
    <material name="geom" texture="texgeom" texuniform="true"/>
  </asset>
  <worldbody>
    <light cutoff="100" diffuse="1 1 1" dir="-0 0 -1.3" directional="true" exponent="1" pos="0 0 1.3" specular=".1 .1 .1"/>
    <geom conaffinity="1" condim="3" material="MatPlane" name="floor" pos="0 0 0" rgba="0.8 0.9 0.8 1" size="40 40 40" type="plane"/>
    <body name="torso" pos="0 0 .7">
      <camera name="track" mode="trackcom" pos="0 -3 0.3" xyaxes="1 0 0 0 0 1"/>
      <joint armature="0" axis="1 0 0" damping="0" limited="false" name="rootx" pos="0 0 0" stiffness="0" type="slide"/>
      <joint armature="0" axis="0 0 1" damping="0" limited="false" name="rootz" pos="0 0 0" stiffness="0" type="slide"/>
      <joint armature="0" axis="0 1 0" damping="0" limited="false" name="rooty" pos="0 0 0" stiffness="0" type="hinge"/>
      <geom fromto="-{{torso_length/2}} 0 0 {{torso_length/2}} 0 0" name="torso" size="0.046" type="capsule"/>
      <geom axisangle="0 1 0 {{head_angle}}" name="head" pos="{{torso_length/2 + head_size*cos(head_angle)}} 0 {{head_size*cos(head_angle)}}" size="0.046 {{head_size}}" type="capsule"/>
      <!-- <site name='tip'  pos='.15 0 .11'/>-->
      <body name="bthigh" pos="-{{torso_length/2}} 0 0">
        <joint axis="0 1 0" damping="6" name="bthigh" pos="0 0 0" range="-.52 1.05" stiffness="240" type="hinge"/>
        <geom axisangle="0 1 0 {{bthigh_angle}}" name="bthigh" pos="{{bthigh_size*sin(bthigh_angle)}} 0 {{bthigh_size*cos(bthigh_angle)}}" size="0.046 {{bthigh_size}}" type="capsule"/>
        <body name="bshin" pos="{{2*bthigh_size*sin(bthigh_angle)}} 0 {{2*bthigh_size*cos(bthigh_angle)}}">
            <joint axis="0 1 0" damping="4.5" name="bshin" pos="0 0 0" range="-.785 .785" stiffness="180" type="hinge"/>
            <geom axisangle="0 1 0 {{bshin_angle}}" name="bshin" pos="{{bshin_size*sin(bshin_angle)}} 0 {{bshin_size*cos(bshin_angle)}}" rgba="0.9 0.6 0.6 1" size="0.046 {{bshin_size}}" type="capsule"/>
            <body name="bfoot" pos="{{2*bshin_size*sin(bshin_angle)}} 0 {{2*bshin_size*cos(bshin_angle)}}">
                <joint axis="0 1 0" damping="3" name="bfoot" pos="0 0 0" range="-.4 .785" stiffness="120" type="hinge"/>
                <geom axisangle="0 1 0 {{bfoot_angle}}" name="bfoot" pos="{{sin(-bfoot_angle)*bfoot_size}} 0 -{{bfoot_size}}" rgba="0.9 0.6 0.6 1" size="0.046 {{bfoot_size}}" type="capsule"/>
            </body>
        </body>
      </body>
      <body name="fthigh" pos="{{torso_length/2}} 0 0">
        <joint axis="0 1 0" damping="4.5" name="fthigh" pos="0 0 0" range="-1 .7" stiffness="180" type="hinge"/>
        <geom axisangle="0 1 0 {{fthigh_angle}}" name="fthigh" pos="{{fthigh_size*sin(-fthigh_angle)}} 0 {{(-1)*fthigh_size*cos(fthigh_angle)}}" size="0.046 {{fthigh_size}}" type="capsule"/>
        <body name="fshin" pos="{{2*fthigh_size*sin(-fthigh_angle)}} 0 {{(-2)*fthigh_size*cos(fthigh_angle)}}">
          <joint axis="0 1 0" damping="3" name="fshin" pos="0 0 0" range="-1.2 .87" stiffness="120" type="hinge"/>
          <geom axisangle="0 1 0 {{fshin_angle}}" name="fshin" pos="{{fshin_size*sin(-fshin_angle)}} 0 {{(-1)*fshin_size*cos(fshin_angle)}}" rgba="0.9 0.6 0.6 1" size="0.046 {{fshin_size}}" type="capsule"/>
          <body name="ffoot" pos="{{2*fshin_size*sin(-fshin_angle)}} 0 {{(-2)*fshin_size*cos(fshin_angle)}}">
            <joint axis="0 1 0" damping="1.5" name="ffoot" pos="0 0 0" range="-.5 .5" stiffness="60" type="hinge"/>
            <geom axisangle="0 1 0 {{ffoot_angle}}" name="ffoot" pos="{{sin(-ffoot_angle)*ffoot_size*9/8}} 0 -{{ffoot_size}}" rgba="0.9 0.6 0.6 1" size="0.046 {{ffoot_size}}" type="capsule"/>
          </body>
        </body>
        </body>
    </body>
  </worldbody>
  <actuator>
    <motor gear="120" joint="bthigh" name="bthigh"/>
    <motor gear="90" joint="bshin" name="bshin"/>
    <motor gear="60" joint="bfoot" name="bfoot"/>
    <motor gear="120" joint="fthigh" name="fthigh"/>
    <motor gear="60" joint="fshin" name="fshin"/>
    <motor gear="30" joint="ffoot" name="ffoot"/>
  </actuator>

  <contact>
      <pair class="foot-floor" geom1="bfoot" geom2="floor" />
      <pair class="foot-floor" geom1="ffoot" geom2="floor" />
  </contact>
</mujoco>
