<mujoco model="walker2d">
  <compiler angle="degree" coordinate="global" inertiafromgeom="true"/>
  <default>
    <joint armature="0.01" damping=".1" limited="true"/>
    <geom conaffinity="0" condim="3" contype="1" density="1000" friction=".7 .1 .1" rgba="0.8 0.6 .4 1"/>


    <!-- http://mujoco.org/book/XMLreference.html#pair -->
    <!-- two tangential, one torsional, two rolling (with condim=3 I only used the first two tangential)-->
    <default class="foot-floor">
           <pair condim="3"/> <!-- Friction coeffs are set in the actual <pair> below -->
    </default>

  </default>

  <!-- <option integrator="RK4" timestep="0.002"/> -->
  <!-- The warmstart flag should be disabled whenever we set the states in random orders so that no information from previous state computations is used. -->
  <option integrator="RK4" timestep="0.002">
     <flag warmstart="disable" /> 
  </option>
  
  <worldbody>
    <light cutoff="100" diffuse="1 1 1" dir="-0 0 -1.3" directional="true" exponent="1" pos="0 0 1.3" specular=".1 .1 .1"/>
    <geom conaffinity="1" condim="3" name="floor" pos="0 0 0" rgba="0.8 0.9 0.8 1" size="40 40 40" type="plane" material="MatPlane"/>
    <body name="torso" pos="0 0 1.25">
      <camera name="track" mode="trackcom" pos="0 -3 1" xyaxes="1 0 0 0 0 1"/>
      <joint armature="0" axis="1 0 0" damping="0" limited="false" name="rootx" pos="0 0 0" stiffness="0" type="slide"/>
      <joint armature="0" axis="0 0 1" damping="0" limited="false" name="rootz" pos="0 0 0" ref="1.25" stiffness="0" type="slide"/>
      <joint armature="0" axis="0 1 0" damping="0" limited="false" name="rooty" pos="0 0 1.25" stiffness="0" type="hinge"/>
      <geom friction="0.9" fromto="0 0 {{ size[1] + size[2] + size[0] }} 0 0 {{ size[1] + size[2] }}" name="torso_geom" size="0.05" type="capsule"/>
      <body name="thigh" pos="0 0 {{size[1] + size[2]}}">
          <joint axis="0 -1 0" name="thigh_joint" pos="0 0 {{size[1] + size[2]}}" range="-150 0" type="hinge"/>
        <geom friction="0.9" fromto="0 0 {{size[1] + size[2]}} 0 0 {{size[2]}}" name="thigh_geom" size="0.05" type="capsule"/>
        <body name="leg" pos="0 0 0.35">
          <joint axis="0 -1 0" name="leg_joint" pos="0 0 {{size[2]}}" range="-150 0" type="hinge"/>
          <geom friction="0.9" fromto="0 0 {{size[2]}} 0 0 0.1" name="leg_geom" size="0.04" type="capsule"/>
          <body name="foot" pos="0.2/2 0 0.1">
            <joint axis="0 -1 0" name="foot_joint" pos="0 0 0.1" range="-45 45" type="hinge"/>
            <geom friction="0.9" fromto="-0.0 0 0.1 {{size[3]}} 0 0.1" name="foot_geom" size="0.06" type="capsule"/>
          </body>
        </body>
      </body>
      <!-- copied and then replace thigh->thigh_left, leg->leg_left, foot->foot_right -->
      <body name="thigh_left" pos="0 0 {{size[1] + size[2]}}">
        <joint axis="0 -1 0" name="thigh_left_joint" pos="0 0 {{size[1] + size[2]}}" range="-150 0" type="hinge"/>
        <geom friction="0.9" fromto="0 0 {{size[1] + size[2]}} 0 0 {{size[2]}}" name="thigh_left_geom" rgba=".7 .3 .6 1" size="0.05" type="capsule"/>
        <body name="leg_left" pos="0 0 0.35">
          <joint axis="0 -1 0" name="leg_left_joint" pos="0 0 {{size[2]}}" range="-150 0" type="hinge"/>
          <geom friction="0.9" fromto="0 0 {{size[2]}} 0 0 0.1" name="leg_left_geom" rgba=".7 .3 .6 1" size="0.04" type="capsule"/>
          <body name="foot_left" pos="0.2/2 0 0.1">
            <joint axis="0 -1 0" name="foot_left_joint" pos="0 0 0.1" range="-45 45" type="hinge"/>
            <geom friction="1.9" fromto="-0.0 0 0.1 {{size[3]}} 0 0.1" name="foot_left_geom" rgba=".7 .3 .6 1" size="0.06" type="capsule"/>
          </body>
        </body>
      </body>
    </body>
</worldbody>
  <actuator>
    <!-- <motor joint="torso_joint" ctrlrange="-100.0 100.0" isctrllimited="true"/>-->
    <motor ctrllimited="true" ctrlrange="-1.0 1.0" gear="100" joint="thigh_joint"/>
    <motor ctrllimited="true" ctrlrange="-1.0 1.0" gear="100" joint="leg_joint"/>
    <motor ctrllimited="true" ctrlrange="-1.0 1.0" gear="100" joint="foot_joint"/>
    <motor ctrllimited="true" ctrlrange="-1.0 1.0" gear="100" joint="thigh_left_joint"/>
    <motor ctrllimited="true" ctrlrange="-1.0 1.0" gear="100" joint="leg_left_joint"/>
    <motor ctrllimited="true" ctrlrange="-1.0 1.0" gear="100" joint="foot_left_joint"/>
    <!-- <motor joint="finger2_rot" ctrlrange="-20.0 20.0" isctrllimited="true"/>-->
  </actuator>

  <contact>
      <pair class="foot-floor" geom1="foot_geom" geom2="floor" friction="0.9 0.9 .1 .1 .1" />
      <pair class="foot-floor" geom1="foot_left_geom" geom2="floor" friction="1.9 1.9 .1 .1 .1" />
  </contact>

    <asset>
        <texture type="skybox" builtin="gradient" rgb1=".4 .5 .6" rgb2="0 0 0"
            width="100" height="100"/>
        <texture builtin="flat" height="1278" mark="cross" markrgb="1 1 1" name="texgeom" random="0.01" rgb1="0.8 0.6 0.4" rgb2="0.8 0.6 0.4" type="cube" width="127"/>
        <texture builtin="checker" height="100" name="texplane" rgb1="0 0 0" rgb2="0.8 0.8 0.8" type="2d" width="100"/>
        <material name="MatPlane" reflectance="0.5" shininess="1" specular="1" texrepeat="60 60" texture="texplane"/>
        <material name="geom" texture="texgeom" texuniform="true"/>
    </asset>
</mujoco>
